Traceback (most recent call last):
  File "C:\Users\wilso\miniconda3\envs\sysidentpy\lib\site-packages\jupyter_cache\executors\utils.py", line 51, in single_nb_execution
    executenb(
  File "C:\Users\wilso\miniconda3\envs\sysidentpy\lib\site-packages\nbclient\client.py", line 1117, in execute
    return NotebookClient(nb=nb, resources=resources, km=km, **kwargs).execute()
  File "C:\Users\wilso\miniconda3\envs\sysidentpy\lib\site-packages\nbclient\util.py", line 78, in wrapped
    return just_run(coro(*args, **kwargs))
  File "C:\Users\wilso\miniconda3\envs\sysidentpy\lib\site-packages\nbclient\util.py", line 57, in just_run
    return loop.run_until_complete(coro)
  File "C:\Users\wilso\miniconda3\envs\sysidentpy\lib\asyncio\base_events.py", line 616, in run_until_complete
    return future.result()
  File "C:\Users\wilso\miniconda3\envs\sysidentpy\lib\site-packages\nbclient\client.py", line 558, in async_execute
    await self.async_execute_cell(
  File "C:\Users\wilso\miniconda3\envs\sysidentpy\lib\site-packages\nbclient\client.py", line 862, in async_execute_cell
    self._check_raise_for_error(cell, exec_reply)
  File "C:\Users\wilso\miniconda3\envs\sysidentpy\lib\site-packages\nbclient\client.py", line 765, in _check_raise_for_error
    raise CellExecutionError.from_cell_and_msg(cell, exec_reply_content)
nbclient.exceptions.CellExecutionError: An error occurred while executing the following cell:
------------------
from sysidentpy.polynomial_basis import AOLS
from sysidentpy.utils.generate_data import get_siso_data
from sysidentpy.metrics import root_relative_squared_error
import pandas as pd
import matplotlib.pyplot as plt

x_train, x_test, y_train, y_test = get_siso_data(
    n=1000, colored_noise=False, sigma=0.001, train_percentage=90
)

model = AOLS(
    xlag=3,
    ylag=3,
    non_degree=2,
    n_inputs=1,
    k=5,
    l=1,
)
------------------

[1;31m---------------------------------------------------------------------------[0m
[1;31mImportError[0m                               Traceback (most recent call last)
[1;32m~\AppData\Local\Temp/ipykernel_5660/2164525957.py[0m in [0;36m<module>[1;34m[0m
[1;32m----> 1[1;33m [1;32mfrom[0m [0msysidentpy[0m[1;33m.[0m[0mpolynomial_basis[0m [1;32mimport[0m [0mAOLS[0m[1;33m[0m[1;33m[0m[0m
[0m[0;32m      2[0m [1;32mfrom[0m [0msysidentpy[0m[1;33m.[0m[0mutils[0m[1;33m.[0m[0mgenerate_data[0m [1;32mimport[0m [0mget_siso_data[0m[1;33m[0m[1;33m[0m[0m
[0;32m      3[0m [1;32mfrom[0m [0msysidentpy[0m[1;33m.[0m[0mmetrics[0m [1;32mimport[0m [0mroot_relative_squared_error[0m[1;33m[0m[1;33m[0m[0m
[0;32m      4[0m [1;32mimport[0m [0mpandas[0m [1;32mas[0m [0mpd[0m[1;33m[0m[1;33m[0m[0m
[0;32m      5[0m [1;32mimport[0m [0mmatplotlib[0m[1;33m.[0m[0mpyplot[0m [1;32mas[0m [0mplt[0m[1;33m[0m[1;33m[0m[0m

[1;31mImportError[0m: cannot import name 'AOLS' from 'sysidentpy.polynomial_basis' (C:\Users\wilso\miniconda3\envs\sysidentpy\lib\site-packages\sysidentpy\polynomial_basis\__init__.py)
ImportError: cannot import name 'AOLS' from 'sysidentpy.polynomial_basis' (C:\Users\wilso\miniconda3\envs\sysidentpy\lib\site-packages\sysidentpy\polynomial_basis\__init__.py)

